Workbook

Sheet Table1
A1: Post ID | B1: Platform | C1: Date | D1: Content Type | E1: Post Text | F1: Likes | G1: Shares | H1: Comments | I1: Impressions | J1: Reach | K1: Clicks | L1: Engagement_Rate | M1: Rank | N1: Value | O1: Total_Engagement
A2: SP001 | B2: Instagram | C2: 45781 | D2: Text | E2: Discover fresh beats on Spotify! | F2: 2414 | G2: 245 | H2: 137 | I2: 21181 | J2: 45292 | K2: 133 | L2: 0.1320051 | M2: 53 | N2: #SoundtrackOfLife | O2: =F2 + G2+H2 -> 2796
A3: SP001 | B3: Instagram | C3: 45781 | D3: Text | E3: Discover fresh beats on Spotify! | F3: 2414 | G3: 245 | H3: 137 | I3: 21181 | J3: 45292 | K3: 133 | L3: 0.1320051 | M3: 53 | N3: #NowPlaying | O3: =F3 + G3+H3 -> 2796
A4: SP002 | B4: Instagram | C4: 45689 | D4: Text | E4: Explore the latest podcasts now. | F4: 1934 | G4: 210 | H4: 393 | I4: 29129 | J4: 73287 | K4: 273 | L4: 0.087095335 | M4: 145 | N4: #DiscoverWeekly | O4: =F4 + G4+H4 -> 2537
A5: SP003 | B5: Twitter | C5: 45629 | D5: Story | E5: New music just dropped. Hit play! | F5: 3092 | G5: 177 | H5: 81 | I5: 47533 | J5: 29220 | K5: 121 | L5: 0.070477353 | M5: 202 | N5: #MusicForEveryone | O5: =F5 + G5+H5 -> 3350
A6: SP003 | B6: Twitter | C6: 45629 | D6: Story | E6: New music just dropped. Hit play! | F6: 3092 | G6: 177 | H6: 81 | I6: 47533 | J6: 29220 | K6: 121 | L6: 0.070477353 | M6: 202 | N6: #NowPlaying | O6: =F6 + G6+H6 -> 3350
A7: SP004 | B7: Instagram | C7: 45629 | D7: Text | E7: Wrapped is here! Relive your top tracks | F7: 3173 | G7: 229 | H7: 197 | I7: 29604 | J7: 21809 | K7: 272 | L7: 0.12157141 | M7: 64 | N7: #SoundtrackOfLife | O7: =F7 + G7+H7 -> 3599
A8: SP004 | B8: Instagram | C8: 45629 | D8: Text | E8: Wrapped is here! Relive your top tracks | F8: 3173 | G8: 229 | H8: 197 | I8: 29604 | J8: 21809 | K8: 272 | L8: 0.12157141 | M8: 64 | N8: #NowPlaying | O8: =F8 + G8+H8 -> 3599
A9: SP005 | B9: YouTube | C9: 45388 | D9: Text | E9: Music that moves you-only on Spotify. | F9: 2748 | G9: 145 | H9: 315 | I9: 24401 | J9: 61182 | K9: 200 | L9: 0.13147002 | M9: 54 | N9: #DiscoverWeekly | O9: =F9 + G9+H9 -> 3208
A10: SP005 | B10: YouTube | C10: 45388 | D10: Text | E10: Music that moves you-only on Spotify. | F10: 2748 | G10: 145 | H10: 315 | I10: 24401 | J10: 61182 | K10: 200 | L10: 0.13147002 | M10: 54 | N10: #SpotifyWrapped | O10: =F10 + G10+H10 -> 3208
A11: SP006 | B11: YouTube | C11: 45456 | D11: Text | E11: What's your vibe today? #SpotifyHits | F11: 3882 | G11: 239 | H11: 275 | I11: 58748 | J11: 44646 | K11: 149 | L11: 0.074828079 | M11: 190 | N11: #DiscoverWeekly | O11: =F11 + G11+H11 -> 4396
A12: SP006 | B12: YouTube | C12: 45456 | D12: Text | E12: What's your vibe today? #SpotifyHits | F12: 3882 | G12: 239 | H12: 275 | I12: 58748 | J12: 44646 | K12: 149 | L12: 0.074828079 | M12: 190 | N12: #SpotifyWrapped | O12: =F12 + G12+H12 -> 4396
A13: SP007 | B13: Twitter | C13: 45645 | D13: Story | E13: Get into the groove with our new drop! | F13: 4674 | G13: 409 | H13: 327 | I13: 20756 | J13: 63599 | K13: 212 | L13: 0.26064752 | M13: 1 | N13: #SoundtrackOfLife | O13: =F13 + G13+H13 -> 5410
... A484: SP300 | B484: Instagram | C484: 45329 | D484: Text | E484: Music that moves you-only on Spotify. | F484: 1883 | G484: 432 | H484: 397 | I484: 28759 | J484: 18691 | K484: 270 | L484: 0.094300914 | M484: 123 | N484: #NowPlaying | O484: =F484 + G484+H484 -> 2712

Sheet Posts
A1: Post ID | B1: Platform | C1: Date | D1: Content Type | E1: Post Text | F1: Likes | G1: Shares | H1: Comments | I1: Impressions | J1: Reach | K1: Clicks | L1: Column1 | M1: Campaign_Name
A2: SP001 | B2: Instagram | C2: 45781 | D2: Text | E2: Discover fresh beats on Spotify! | F2: 2414 | G2: 245 | H2: 137 | I2: 21181 | J2: 45292 | K2: 133 | L2: Hashtags Used | M2: ChillVibes
A3: SP002 | B3: Instagram | C3: 45689 | D3: Text | E3: Explore the latest podcasts now. | F3: 1934 | G3: 210 | H3: 393 | I3: 29129 | J3: 73287 | K3: 273 | L3: #SoundtrackOfLife,#NowPlaying | M3: IndieWave
A4: SP003 | B4: Twitter | C4: 45629 | D4: Story | E4: New music just dropped. Hit play! | F4: 3092 | G4: 177 | H4: 81 | I4: 47533 | J4: 29220 | K4: 121 | L4: #DiscoverWeekly | M4: ChillVibes
A5: SP004 | B5: Instagram | C5: 45629 | D5: Text | E5: Wrapped is here! Relive your top tracks ðŸŽ§ | F5: 3173 | G5: 229 | H5: 197 | I5: 29604 | J5: 21809 | K5: 272 | L5: #MusicForEveryone,#NowPlaying | M5: ChillVibes
A6: SP005 | B6: YouTube | C6: 45388 | D6: Text | E6: Music that moves youâ€”only on Spotify. | F6: 2748 | G6: 145 | H6: 315 | I6: 24401 | J6: 61182 | K6: 200 | L6: #SoundtrackOfLife,#NowPlaying | M6: IndieWave
A7: SP006 | B7: YouTube | C7: 45456 | D7: Text | E7: Whatâ€™s your vibe today? #SpotifyHits | F7: 3882 | G7: 239 | H7: 275 | I7: 58748 | J7: 44646 | K7: 149 | L7: #DiscoverWeekly,#SpotifyWrapped | M7: IndieWave
A8: SP007 | B8: Twitter | C8: 45645 | D8: Story | E8: Get into the groove with our new drop! | F8: 4674 | G8: 409 | H8: 327 | I8: 20756 | J8: 63599 | K8: 212 | L8: #DiscoverWeekly,#SpotifyWrapped | M8: ChillVibes
A9: SP008 | B9: Twitter | C9: 45421 | D9: Story | E9: Wrapped is here! Relive your top tracks ðŸŽ§ | F9: 1428 | G9: 347 | H9: 67 | I9: 21148 | J9: 19712 | K9: 120 | L9: #SoundtrackOfLife,#NowPlaying | M9: ChillVibes
A10: SP009 | B10: Twitter | C10: 45823 | D10: Text | E10: Top trending tracks updated daily! | F10: 4432 | G10: 223 | H10: 299 | I10: 59016 | J10: 21742 | K10: 171 | L10: #DiscoverWeekly,#MusicForEveryone | M10: ChillVibes
A11: SP010 | B11: Twitter | C11: 45630 | D11: Text | E11: Wrapped is here! Relive your top tracks ðŸŽ§ | F11: 2357 | G11: 274 | H11: 172 | I11: 21566 | J11: 66829 | K11: 284 | L11: #NowPlaying | M11: ChillVibes
A12: SP011 | B12: Twitter | C12: 45357 | D12: Text | E12: Discover fresh beats on Spotify! | F12: 1971 | G12: 370 | H12: 306 | I12: 31316 | J12: 27897 | K12: 88 | L12: #NowPlaying | M12: IndieWave
A13: SP012 | B13: Instagram | C13: 45426 | D13: Text | E13: Discover fresh beats on Spotify! | F13: 1485 | G13: 353 | H13: 244 | I13: 38419 | J13: 38556 | K13: 86 | L13: #SoundtrackOfLife | M13: ChillVibes
... A301: SP300 | B301: Instagram | C301: 45329 | D301: Text | E301: Music that moves youâ€”only on Spotify. | F301: 1883 | G301: 432 | H301: 397 | I301: 28759 | J301: 18691 | K301: 270 | L301: #DiscoverWeekly,#MusicForEveryone | M301: ChillVibes
L302: #SoundtrackOfLife,#NowPlaying

Sheet Engagement Summary
A1: Week_Start_Date | B1: Platform | C1: New_Followers | D1: Unfollows | E1: Total_Followers | F1: Engagement_Rate | G1: Ad_Spend
A2: 45446 | B2: Instagram | C2: 1402 | D2: 68 | E2: 124562 | F2: 9.92 | G2: 23125
A3: 45446 | B3: Twitter | C3: 995 | D3: 86 | E3: 227958 | F3: 8.05 | G3: 22788
A4: 45446 | B4: YouTube | C4: 1472 | D4: 296 | E4: 370242 | F4: 7.72 | G4: 7810
A5: 45453 | B5: Instagram | C5: 1018 | D5: 90 | E5: 92474 | F5: 9.4 | G5: 11966
A6: 45453 | B6: Twitter | C6: 1461 | D6: 64 | E6: 328902 | F6: 9.02 | G6: 26298
A7: 45453 | B7: YouTube | C7: 545 | D7: 93 | E7: 391621 | F7: 9.96 | G7: 22029
A8: 45460 | B8: Instagram | C8: 881 | D8: 291 | E8: 95885 | F8: 5.29 | G8: 12391
A9: 45460 | B9: Twitter | C9: 1414 | D9: 131 | E9: 245947 | F9: 8.3 | G9: 14477
A10: 45460 | B10: YouTube | C10: 1472 | D10: 170 | E10: 250428 | F10: 4.66 | G10: 25040
A11: 45467 | B11: Instagram | C11: 809 | D11: 197 | E11: 87186 | F11: 9.48 | G11: 22619
A12: 45467 | B12: Twitter | C12: 1371 | D12: 250 | E12: 128620 | F12: 7.11 | G12: 12399
A13: 45467 | B13: YouTube | C13: 844 | D13: 144 | E13: 126015 | F13: 9.65 | G13: 22456
... A201: 45908 | B201: Twitter | C201: 860 | D201: 244 | E201: 348686 | F201: 5.12 | G201: 11418

Sheet Campaign Metadata
A1: Campaign_Name | B1: Start_Date | C1: End_Date | D1: Objective | E1: Total_Budget | F1: Target_Platforms | G1: Primary_Hashtags
A2: SummerBeats | B2: 2024-06-15 | C2: 2024-07-15 | D2: Brand Awareness | E2: 175000 | F2: Instagram,YouTube | G2: #SpotifyWrapped,#MusicForEveryone
A3: Wrapped2024 | B3: 2024-12-01 | C3: 2024-12-31 | D3: Engagement | E3: 225000 | F3: Twitter,YouTube | G3: #SpotifyWrapped,#NowPlaying
A4: ChillVibes | B4: 2025-01-10 | C4: 2025-02-10 | D4: Product Launch | E4: 200000 | F4: Instagram,Twitter | G4: #ChillVibes,#SoundtrackOfLife
A5: IndieWave | B5: 2025-03-01 | C5: 2025-03-31 | D5: Traffic | E5: 160000 | F5: Facebook,Instagram | G5: #DiscoverWeekly,#IndieWave

Sheet Posts_clean
A1: Post ID | B1: Platform | C1: Date | D1: Content Type | E1: Post Text | F1: Likes | G1: Shares | H1: Comments | I1: Impressions | J1: Reach | K1: Clicks | L1: Hashtag_1 | M1: Hashtag_2 | N1: Engagement_Rate | O1: Rank | P1: Total_Engagement | Q1: Campaign_Name | R1: Campaign_Period | S1: Impact_Period | X1: start | Y1: end | Z1: Before | AA1: During | AB1: lift
A2: SP001 | B2: Instagram | C2: 45781 | D2: Text | E2: Discover fresh beats on Spotify! | F2: 2414 | G2: 245 | H2: 137 | I2: 21181 | J2: 45292 | K2: 133 | L2: #SoundtrackOfLife | M2: #NowPlaying | N2: =(F2+G2+H2)/I2 -> 0.1320051 | O2: =RANK(N2,$N:$N,0) -> 53 | P2: =F2+G2+H2 -> 2796 | Q2: =IF(AND(--$C2>=--Campaign_Metadata_clean!$B$2,--$C2<=--Campaign_Metadata_clean!$C$2),"SummerBeats", IF(AND(--$C2>=--Campaign_Metadata_clean!$B$3,--$C2<=--Campaign_Metadata_clean!$C$3),"Wrapped2024", IF(AND(--$C2>=--Campaign_Metadata_clean!$B$4,--$C2<=--Campaign_Metadata_clean!$C$4),"ChillVibes", IF(AND(--$C2>=--Campaign_Metadata_clean!$B$5,--$C2<=--Campaign_Metadata_clean!$C$5),"IndieWave","No Campaign")))) -> No Campaign | R2: =IF(AND(C2>=DATE(2025,1,10), C2<=DATE(2025,2,10)), "During", IF(C2<DATE(2025,1,10), "Before", "Other")) -> Other | S2: =IF(OR(X2="",Y2=""),"", IF(AND(C2>=X2-30,C2<X2),"Before", IF(AND(C2>=X2,C2<=Y2),"During","Other"))) | X2: =IFERROR( _xlfn.XLOOKUP(Q2, Campaign_Metadata_clean!A:A, Campaign_Metadata_clean!B:B), "") | Y2: =IFERROR( _xlfn.XLOOKUP(Q2, Campaign_Metadata_clean!A:A, Campaign_Metadata_clean!C:C), "") | Z2: =IFERROR( AVERAGEIFS(N:N, C:C, ">=" & X2-30, C:C, "<" & X2), 0) -> 0 | AA2: =IFERROR( AVERAGEIFS(N:N, C:C, ">=" & X2, C:C, "<=" & Y2), 0) -> 0 | AB2: =IF(AA2=0,0,(AB2-AA2)/AA2) -> 0
A3: SP002 | B3: Instagram | C3: 45689 | D3: Text | E3: Explore the latest podcasts now. | F3: 1934 | G3: 210 | H3: 393 | I3: 29129 | J3: 73287 | K3: 273 | L3: #DiscoverWeekly | N3: =(F3+G3+H3)/I3 -> 0.087095335 | O3: =RANK(N3,$N:$N,0) -> 145 | P3: =F3+G3+H3 -> 2537 | Q3: =IF(AND(--$C3>=--Campaign_Metadata_clean!$B$2,--$C3<=--Campaign_Metadata_clean!$C$2),"SummerBeats", IF(AND(--$C3>=--Campaign_Metadata_clean!$B$3,--$C3<=--Campaign_Metadata_clean!$C$3),"Wrapped2024", IF(AND(--$C3>=--Campaign_Metadata_clean!$B$4,--$C3<=--Campaign_Metadata_clean!$C$4),"ChillVibes", IF(AND(--$C3>=--Campaign_Metadata_clean!$B$5,--$C3<=--Campaign_Metadata_clean!$C$5),"IndieWave","No Campaign")))) -> ChillVibes | R3: =IF(AND(C3>=DATE(2025,1,10), C3<=DATE(2025,2,10)), "During", IF(C3<DATE(2025,1,10), "Before", "Other")) -> During | S3: =IF(OR(X3="",Y3=""),"", IF(AND(C3>=X3-30,C3<X3),"Before", IF(AND(C3>=X3,C3<=Y3),"During","Other"))) -> During | X3: =IFERROR( _xlfn.XLOOKUP(Q3, Campaign_Metadata_clean!A:A, Campaign_Metadata_clean!B:B), "") -> 45667 | Y3: =IFERROR( _xlfn.XLOOKUP(Q3, Campaign_Metadata_clean!A:A, Campaign_Metadata_clean!C:C), "") -> 45698 | Z3: =IFERROR( AVERAGEIFS(N:N, C:C, ">=" & X3-30, C:C, "<" & X3), 0) -> 0.10086312 | AA3: =IFERROR( AVERAGEIFS(N:N, C:C, ">=" & X3, C:C, "<=" & Y3), 0) -> 0.1054116 | AB3: =IF(AA3=0,0,(AB3-AA3)/AA3) -> 0
A4: SP003 | B4: Twitter | C4: 45629 | D4: Story | E4: New music just dropped. Hit play! | F4: 3092 | G4: 177 | H4: 81 | I4: 47533 | J4: 29220 | K4: 121 | L4: #MusicForEveryone | M4: #NowPlaying | N4: =(F4+G4+H4)/I4 -> 0.070477353 | O4: =RANK(N4,$N:$N,0) -> 202 | P4: =F4+G4+H4 -> 3350 | Q4: =IF(AND(--$C4>=--Campaign_Metadata_clean!$B$2,--$C4<=--Campaign_Metadata_clean!$C$2),"SummerBeats", IF(AND(--$C4>=--Campaign_Metadata_clean!$B$3,--$C4<=--Campaign_Metadata_clean!$C$3),"Wrapped2024", IF(AND(--$C4>=--Campaign_Metadata_clean!$B$4,--$C4<=--Campaign_Metadata_clean!$C$4),"ChillVibes", IF(AND(--$C4>=--Campaign_Metadata_clean!$B$5,--$C4<=--Campaign_Metadata_clean!$C$5),"IndieWave","No Campaign")))) -> Wrapped2024 | R4: =IF(AND(C4>=DATE(2025,1,10), C4<=DATE(2025,2,10)), "During", IF(C4<DATE(2025,1,10), "Before", "Other")) -> Before | S4: =IF(OR(X4="",Y4=""),"", IF(AND(C4>=X4-30,C4<X4),"Before", IF(AND(C4>=X4,C4<=Y4),"During","Other"))) -> During | X4: =IFERROR( _xlfn.XLOOKUP(Q4, Campaign_Metadata_clean!A:A, Campaign_Metadata_clean!B:B), "") -> 45627 | Y4: =IFERROR( _xlfn.XLOOKUP(Q4, Campaign_Metadata_clean!A:A, Campaign_Metadata_clean!C:C), "") -> 45657 | Z4: =IFERROR( AVERAGEIFS(N:N, C:C, ">=" & X4-30, C:C, "<" & X4), 0) -> 0.092680819 | AA4: =IFERROR( AVERAGEIFS(N:N, C:C, ">=" & X4, C:C, "<=" & Y4), 0) -> 0.099294725 | AB4: =IF(AA4=0,0,(AB4-AA4)/AA4) -> 0
A5: SP004 | B5: Instagram | C5: 45629 | D5: Text | E5: Wrapped is here! Relive your top tracks | F5: 3173 | G5: 229 | H5: 197 | I5: 29604 | J5: 21809 | K5: 272 | L5: #SoundtrackOfLife | M5: #NowPlaying | N5: =(F5+G5+H5)/I5 -> 0.12157141 | O5: =RANK(N5,$N:$N,0) -> 64 | P5: =F5+G5+H5 -> 3599 | Q5: =IF(AND(--$C5>=--Campaign_Metadata_clean!$B$2,--$C5<=--Campaign_Metadata_clean!$C$2),"SummerBeats", IF(AND(--$C5>=--Campaign_Metadata_clean!$B$3,--$C5<=--Campaign_Metadata_clean!$C$3),"Wrapped2024", IF(AND(--$C5>=--Campaign_Metadata_clean!$B$4,--$C5<=--Campaign_Metadata_clean!$C$4),"ChillVibes", IF(AND(--$C5>=--Campaign_Metadata_clean!$B$5,--$C5<=--Campaign_Metadata_clean!$C$5),"IndieWave","No Campaign")))) -> Wrapped2024 | R5: =IF(AND(C5>=DATE(2025,1,10), C5<=DATE(2025,2,10)), "During", IF(C5<DATE(2025,1,10), "Before", "Other")) -> Before | S5: =IF(OR(X5="",Y5=""),"", IF(AND(C5>=X5-30,C5<X5),"Before", IF(AND(C5>=X5,C5<=Y5),"During","Other"))) -> During | X5: =IFERROR( _xlfn.XLOOKUP(Q5, Campaign_Metadata_clean!A:A, Campaign_Metadata_clean!B:B), "") -> 45627 | Y5: =IFERROR( _xlfn.XLOOKUP(Q5, Campaign_Metadata_clean!A:A, Campaign_Metadata_clean!C:C), "") -> 45657 | Z5: =IFERROR( AVERAGEIFS(N:N, C:C, ">=" & X5-30, C:C, "<" & X5), 0) -> 0.092680819 | AA5: =IFERROR( AVERAGEIFS(N:N, C:C, ">=" & X5, C:C, "<=" & Y5), 0) -> 0.099294725 | AB5: =IF(AA5=0,0,(AB5-AA5)/AA5) -> 0
A6: SP005 | B6: YouTube | C6: 45388 | D6: Text | E6: Music that moves you-only on Spotify. | F6: 2748 | G6: 145 | H6: 315 | I6: 24401 | J6: 61182 | K6: 200 | L6: #DiscoverWeekly | M6: #SpotifyWrapped | N6: =(F6+G6+H6)/I6 -> 0.13147002 | O6: =RANK(N6,$N:$N,0) -> 54 | P6: =F6+G6+H6 -> 3208 | Q6: =IF(AND(--$C6>=--Campaign_Metadata_clean!$B$2,--$C6<=--Campaign_Metadata_clean!$C$2),"SummerBeats", IF(AND(--$C6>=--Campaign_Metadata_clean!$B$3,--$C6<=--Campaign_Metadata_clean!$C$3),"Wrapped2024", IF(AND(--$C6>=--Campaign_Metadata_clean!$B$4,--$C6<=--Campaign_Metadata_clean!$C$4),"ChillVibes", IF(AND(--$C6>=--Campaign_Metadata_clean!$B$5,--$C6<=--Campaign_Metadata_clean!$C$5),"IndieWave","No Campaign")))) -> No Campaign | R6: =IF(AND(C6>=DATE(2025,1,10), C6<=DATE(2025,2,10)), "During", IF(C6<DATE(2025,1,10), "Before", "Other")) -> Before | S6: =IF(OR(X6="",Y6=""),"", IF(AND(C6>=X6-30,C6<X6),"Before", IF(AND(C6>=X6,C6<=Y6),"During","Other"))) | X6: =IFERROR( _xlfn.XLOOKUP(Q6, Campaign_Metadata_clean!A:A, Campaign_Metadata_clean!B:B), "") | Y6: =IFERROR( _xlfn.XLOOKUP(Q6, Campaign_Metadata_clean!A:A, Campaign_Metadata_clean!C:C), "") | Z6: =IFERROR( AVERAGEIFS(N:N, C:C, ">=" & X6-30, C:C, "<" & X6), 0) -> 0 | AA6: =IFERROR( AVERAGEIFS(N:N, C:C, ">=" & X6, C:C, "<=" & Y6), 0) -> 0 | AB6: =IF(AA6=0,0,(AB6-AA6)/AA6) -> 0
A7: SP006 | B7: YouTube | C7: 45456 | D7: Text | E7: What's your vibe today? #SpotifyHits | F7: 3882 | G7: 239 | H7: 275 | I7: 58748 | J7: 44646 | K7: 149 | L7: #DiscoverWeekly | M7: #SpotifyWrapped | N7: =(F7+G7+H7)/I7 -> 0.074828079 | O7: =RANK(N7,$N:$N,0) -> 190 | P7: =F7+G7+H7 -> 4396 | Q7: =IF(AND(--$C7>=--Campaign_Metadata_clean!$B$2,--$C7<=--Campaign_Metadata_clean!$C$2),"SummerBeats", IF(AND(--$C7>=--Campaign_Metadata_clean!$B$3,--$C7<=--Campaign_Metadata_clean!$C$3),"Wrapped2024", IF(AND(--$C7>=--Campaign_Metadata_clean!$B$4,--$C7<=--Campaign_Metadata_clean!$C$4),"ChillVibes", IF(AND(--$C7>=--Campaign_Metadata_clean!$B$5,--$C7<=--Campaign_Metadata_clean!$C$5),"IndieWave","No Campaign")))) -> No Campaign | R7: =IF(AND(C7>=DATE(2025,1,10), C7<=DATE(2025,2,10)), "During", IF(C7<DATE(2025,1,10), "Before", "Other")) -> Before | S7: =IF(OR(X7="",Y7=""),"", IF(AND(C7>=X7-30,C7<X7),"Before", IF(AND(C7>=X7,C7<=Y7),"During","Other"))) | X7: =IFERROR( _xlfn.XLOOKUP(Q7, Campaign_Metadata_clean!A:A, Campaign_Metadata_clean!B:B), "") | Y7: =IFERROR( _xlfn.XLOOKUP(Q7, Campaign_Metadata_clean!A:A, Campaign_Metadata_clean!C:C), "") | Z7: =IFERROR( AVERAGEIFS(N:N, C:C, ">=" & X7-30, C:C, "<" & X7), 0) -> 0 | AA7: =IFERROR( AVERAGEIFS(N:N, C:C, ">=" & X7, C:C, "<=" & Y7), 0) -> 0 | AB7: =IF(AA7=0,0,(AB7-AA7)/AA7) -> 0
A8: SP007 | B8: Twitter | C8: 45645 | D8: Story | E8: Get into the groove with our new drop! | F8: 4674 | G8: 409 | H8: 327 | I8: 20756 | J8: 63599 | K8: 212 | L8: #SoundtrackOfLife | M8: #NowPlaying | N8: =(F8+G8+H8)/I8 -> 0.26064752 | O8: =RANK(N8,$N:$N,0) -> 1 | P8: =F8+G8+H8 -> 5410 | Q8: =IF(AND(--$C8>=--Campaign_Metadata_clean!$B$2,--$C8<=--Campaign_Metadata_clean!$C$2),"SummerBeats", IF(AND(--$C8>=--Campaign_Metadata_clean!$B$3,--$C8<=--Campaign_Metadata_clean!$C$3),"Wrapped2024", IF(AND(--$C8>=--Campaign_Metadata_clean!$B$4,--$C8<=--Campaign_Metadata_clean!$C$4),"ChillVibes", IF(AND(--$C8>=--Campaign_Metadata_clean!$B$5,--$C8<=--Campaign_Metadata_clean!$C$5),"IndieWave","No Campaign")))) -> Wrapped2024 | R8: =IF(AND(C8>=DATE(2025,1,10), C8<=DATE(2025,2,10)), "During", IF(C8<DATE(2025,1,10), "Before", "Other")) -> Before | S8: =IF(OR(X8="",Y8=""),"", IF(AND(C8>=X8-30,C8<X8),"Before", IF(AND(C8>=X8,C8<=Y8),"During","Other"))) -> During | X8: =IFERROR( _xlfn.XLOOKUP(Q8, Campaign_Metadata_clean!A:A, Campaign_Metadata_clean!B:B), "") -> 45627 | Y8: =IFERROR( _xlfn.XLOOKUP(Q8, Campaign_Metadata_clean!A:A, Campaign_Metadata_clean!C:C), "") -> 45657 | Z8: =IFERROR( AVERAGEIFS(N:N, C:C, ">=" & X8-30, C:C, "<" & X8), 0) -> 0.092680819 | AA8: =IFERROR( AVERAGEIFS(N:N, C:C, ">=" & X8, C:C, "<=" & Y8), 0) -> 0.099294725 | AB8: =IF(AA8=0,0,(AB8-AA8)/AA8) -> 0
A9: SP008 | B9: Twitter | C9: 45421 | D9: Story | E9: Wrapped is here! Relive your top tracks | F9: 1428 | G9: 347 | H9: 67 | I9: 21148 | J9: 19712 | K9: 120 | L9: #DiscoverWeekly | M9: #MusicForEveryone | N9: =(F9+G9+H9)/I9 -> 0.087100435 | O9: =RANK(N9,$N:$N,0) -> 144 | P9: =F9+G9+H9 -> 1842 | Q9: =IF(AND(--$C9>=--Campaign_Metadata_clean!$B$2,--$C9<=--Campaign_Metadata_clean!$C$2),"SummerBeats", IF(AND(--$C9>=--Campaign_Metadata_clean!$B$3,--$C9<=--Campaign_Metadata_clean!$C$3),"Wrapped2024", IF(AND(--$C9>=--Campaign_Metadata_clean!$B$4,--$C9<=--Campaign_Metadata_clean!$C$4),"ChillVibes", IF(AND(--$C9>=--Campaign_Metadata_clean!$B$5,--$C9<=--Campaign_Metadata_clean!$C$5),"IndieWave","No Campaign")))) -> No Campaign | R9: =IF(AND(C9>=DATE(2025,1,10), C9<=DATE(2025,2,10)), "During", IF(C9<DATE(2025,1,10), "Before", "Other")) -> Before | S9: =IF(OR(X9="",Y9=""),"", IF(AND(C9>=X9-30,C9<X9),"Before", IF(AND(C9>=X9,C9<=Y9),"During","Other"))) | X9: =IFERROR( _xlfn.XLOOKUP(Q9, Campaign_Metadata_clean!A:A, Campaign_Metadata_clean!B:B), "") | Y9: =IFERROR( _xlfn.XLOOKUP(Q9, Campaign_Metadata_clean!A:A, Campaign_Metadata_clean!C:C), "") | Z9: =IFERROR( AVERAGEIFS(N:N, C:C, ">=" & X9-30, C:C, "<" & X9), 0) -> 0 | AA9: =IFERROR( AVERAGEIFS(N:N, C:C, ">=" & X9, C:C, "<=" & Y9), 0) -> 0 | AB9: =IF(AA9=0,0,(AB9-AA9)/AA9) -> 0
A10: SP009 | B10: Twitter | C10: 45823 | D10: Text | E10: Top trending tracks updated daily! | F10: 4432 | G10: 223 | H10: 299 | I10: 59016 | J10: 21742 | K10: 171 | L10: #NowPlaying | N10: =(F10+G10+H10)/I10 -> 0.083943337 | O10: =RANK(N10,$N:$N,0) -> 162 | P10: =F10+G10+H10 -> 4954 | Q10: =IF(AND(--$C10>=--Campaign_Metadata_clean!$B$2,--$C10<=--Campaign_Metadata_clean!$C$2),"SummerBeats", IF(AND(--$C10>=--Campaign_Metadata_clean!$B$3,--$C10<=--Campaign_Metadata_clean!$C$3),"Wrapped2024", IF(AND(--$C10>=--Campaign_Metadata_clean!$B$4,--$C10<=--Campaign_Metadata_clean!$C$4),"ChillVibes", IF(AND(--$C10>=--Campaign_Metadata_clean!$B$5,--$C10<=--Campaign_Metadata_clean!$C$5),"IndieWave","No Campaign")))) -> No Campaign | R10: =IF(AND(C10>=DATE(2025,1,10), C10<=DATE(2025,2,10)), "During", IF(C10<DATE(2025,1,10), "Before", "Other")) -> Other | S10: =IF(OR(X10="",Y10=""),"", IF(AND(C10>=X10-30,C10<X10),"Before", IF(AND(C10>=X10,C10<=Y10),"During","Other"))) | X10: =IFERROR( _xlfn.XLOOKUP(Q10, Campaign_Metadata_clean!A:A, Campaign_Metadata_clean!B:B), "") | Y10: =IFERROR( _xlfn.XLOOKUP(Q10, Campaign_Metadata_clean!A:A, Campaign_Metadata_clean!C:C), "") | Z10: =IFERROR( AVERAGEIFS(N:N, C:C, ">=" & X10-30, C:C, "<" & X10), 0) -> 0 | AA10: =IFERROR( AVERAGEIFS(N:N, C:C, ">=" & X10, C:C, "<=" & Y10), 0) -> 0 | AB10: =IF(AA10=0,0,(AB10-AA10)/AA10) -> 0
A11: SP010 | B11: Twitter | C11: 45630 | D11: Text | E11: Wrapped is here! Relive your top tracks | F11: 2357 | G11: 274 | H11: 172 | I11: 21566 | J11: 66829 | K11: 284 | L11: #NowPlaying | N11: =(F11+G11+H11)/I11 -> 0.12997311 | O11: =RANK(N11,$N:$N,0) -> 56 | P11: =F11+G11+H11 -> 2803 | Q11: =IF(AND(--$C11>=--Campaign_Metadata_clean!$B$2,--$C11<=--Campaign_Metadata_clean!$C$2),"SummerBeats", IF(AND(--$C11>=--Campaign_Metadata_clean!$B$3,--$C11<=--Campaign_Metadata_clean!$C$3),"Wrapped2024", IF(AND(--$C11>=--Campaign_Metadata_clean!$B$4,--$C11<=--Campaign_Metadata_clean!$C$4),"ChillVibes", IF(AND(--$C11>=--Campaign_Metadata_clean!$B$5,--$C11<=--Campaign_Metadata_clean!$C$5),"IndieWave","No Campaign")))) -> Wrapped2024 | R11: =IF(AND(C11>=DATE(2025,1,10), C11<=DATE(2025,2,10)), "During", IF(C11<DATE(2025,1,10), "Before", "Other")) -> Before | S11: =IF(OR(X11="",Y11=""),"", IF(AND(C11>=X11-30,C11<X11),"Before", IF(AND(C11>=X11,C11<=Y11),"During","Other"))) -> During | X11: =IFERROR( _xlfn.XLOOKUP(Q11, Campaign_Metadata_clean!A:A, Campaign_Metadata_clean!B:B), "") -> 45627 | Y11: =IFERROR( _xlfn.XLOOKUP(Q11, Campaign_Metadata_clean!A:A, Campaign_Metadata_clean!C:C), "") -> 45657 | Z11: =IFERROR( AVERAGEIFS(N:N, C:C, ">=" & X11-30, C:C, "<" & X11), 0) -> 0.092680819 | AA11: =IFERROR( AVERAGEIFS(N:N, C:C, ">=" & X11, C:C, "<=" & Y11), 0) -> 0.099294725 | AB11: =IF(AA11=0,0,(AB11-AA11)/AA11) -> 0
A12: SP011 | B12: Twitter | C12: 45357 | D12: Text | E12: Discover fresh beats on Spotify! | F12: 1971 | G12: 370 | H12: 306 | I12: 31316 | J12: 27897 | K12: 88 | L12: #SoundtrackOfLife | N12: =(F12+G12+H12)/I12 -> 0.084525482 | O12: =RANK(N12,$N:$N,0) -> 158 | P12: =F12+G12+H12 -> 2647 | Q12: =IF(AND(--$C12>=--Campaign_Metadata_clean!$B$2,--$C12<=--Campaign_Metadata_clean!$C$2),"SummerBeats", IF(AND(--$C12>=--Campaign_Metadata_clean!$B$3,--$C12<=--Campaign_Metadata_clean!$C$3),"Wrapped2024", IF(AND(--$C12>=--Campaign_Metadata_clean!$B$4,--$C12<=--Campaign_Metadata_clean!$C$4),"ChillVibes", IF(AND(--$C12>=--Campaign_Metadata_clean!$B$5,--$C12<=--Campaign_Metadata_clean!$C$5),"IndieWave","No Campaign")))) -> No Campaign | R12: =IF(AND(C12>=DATE(2025,1,10), C12<=DATE(2025,2,10)), "During", IF(C12<DATE(2025,1,10), "Before", "Other")) -> Before | S12: =IF(OR(X12="",Y12=""),"", IF(AND(C12>=X12-30,C12<X12),"Before", IF(AND(C12>=X12,C12<=Y12),"During","Other"))) | X12: =IFERROR( _xlfn.XLOOKUP(Q12, Campaign_Metadata_clean!A:A, Campaign_Metadata_clean!B:B), "") | Y12: =IFERROR( _xlfn.XLOOKUP(Q12, Campaign_Metadata_clean!A:A, Campaign_Metadata_clean!C:C), "") | Z12: =IFERROR( AVERAGEIFS(N:N, C:C, ">=" & X12-30, C:C, "<" & X12), 0) -> 0 | AA12: =IFERROR( AVERAGEIFS(N:N, C:C, ">=" & X12, C:C, "<=" & Y12), 0) -> 0 | AB12: =IF(AA12=0,0,(AB12-AA12)/AA12) -> 0
A13: SP012 | B13: Instagram | C13: 45426 | D13: Text | E13: Discover fresh beats on Spotify! | F13: 1485 | G13: 353 | H13: 244 | I13: 38419 | J13: 38556 | K13: 86 | L13: #SoundtrackOfLife | M13: #NowPlaying | N13: =(F13+G13+H13)/I13 -> 0.054191936 | O13: =RANK(N13,$N:$N,0) -> 241 | P13: =F13+G13+H13 -> 2082 | Q13: =IF(AND(--$C13>=--Campaign_Metadata_clean!$B$2,--$C13<=--Campaign_Metadata_clean!$C$2),"SummerBeats", IF(AND(--$C13>=--Campaign_Metadata_clean!$B$3,--$C13<=--Campaign_Metadata_clean!$C$3),"Wrapped2024", IF(AND(--$C13>=--Campaign_Metadata_clean!$B$4,--$C13<=--Campaign_Metadata_clean!$C$4),"ChillVibes", IF(AND(--$C13>=--Campaign_Metadata_clean!$B$5,--$C13<=--Campaign_Metadata_clean!$C$5),"IndieWave","No Campaign")))) -> No Campaign | R13: =IF(AND(C13>=DATE(2025,1,10), C13<=DATE(2025,2,10)), "During", IF(C13<DATE(2025,1,10), "Before", "Other")) -> Before | S13: =IF(OR(X13="",Y13=""),"", IF(AND(C13>=X13-30,C13<X13),"Before", IF(AND(C13>=X13,C13<=Y13),"During","Other"))) | X13: =IFERROR( _xlfn.XLOOKUP(Q13, Campaign_Metadata_clean!A:A, Campaign_Metadata_clean!B:B), "") | Y13: =IFERROR( _xlfn.XLOOKUP(Q13, Campaign_Metadata_clean!A:A, Campaign_Metadata_clean!C:C), "") | Z13: =IFERROR( AVERAGEIFS(N:N, C:C, ">=" & X13-30, C:C, "<" & X13), 0) -> 0 | AA13: =IFERROR( AVERAGEIFS(N:N, C:C, ">=" & X13, C:C, "<=" & Y13), 0) -> 0 | AB13: =IF(AA13=0,0,(AB13-AA13)/AA13) -> 0
A14: SP013 | B14: Twitter | C14: 45826 | D14: Story | E14: Discover fresh beats on Spotify! | F14: 3956 | G14: 319 | H14: 61 | I14: 58162 | J14: 28720 | K14: 213 | L14: #MusicForEveryone | M14: #NowPlaying | N14: =(F14+G14+H14)/I14 -> 0.074550394 | O14: =RANK(N14,$N:$N,0) -> 191 | P14: =F14+G14+H14 -> 4336 | Q14: =IF(AND(--$C14>=--Campaign_Metadata_clean!$B$2,--$C14<=--Campaign_Metadata_clean!$C$2),"SummerBeats", IF(AND(--$C14>=--Campaign_Metadata_clean!$B$3,--$C14<=--Campaign_Metadata_clean!$C$3),"Wrapped2024", IF(AND(--$C14>=--Campaign_Metadata_clean!$B$4,--$C14<=--Campaign_Metadata_clean!$C$4),"ChillVibes", IF(AND(--$C14>=--Campaign_Metadata_clean!$B$5,--$C14<=--Campaign_Metadata_clean!$C$5),"IndieWave","No Campaign")))) -> No Campaign | R14: =IF(AND(C14>=DATE(2025,1,10), C14<=DATE(2025,2,10)), "During", IF(C14<DATE(2025,1,10), "Before", "Other")) -> Other | S14: =IF(OR(X14="",Y14=""),"", IF(AND(C14>=X14-30,C14<X14),"Before", IF(AND(C14>=X14,C14<=Y14),"During","Other"))) | X14: =IFERROR( _xlfn.XLOOKUP(Q14, Campaign_Metadata_clean!A:A, Campaign_Metadata_clean!B:B), "") | Y14: =IFERROR( _xlfn.XLOOKUP(Q14, Campaign_Metadata_clean!A:A, Campaign_Metadata_clean!C:C), "") | Z14: =IFERROR( AVERAGEIFS(N:N, C:C, ">=" & X14-30, C:C, "<" & X14), 0) -> 0 | AA14: =IFERROR( AVERAGEIFS(N:N, C:C, ">=" & X14, C:C, "<=" & Y14), 0) -> 0 | AB14: =IF(AA14=0,0,(AB14-AA14)/AA14) -> 0
A15: SP014 | B15: Twitter | C15: 45573 | D15: Text | E15: From pop to podcasts, it's all here. | F15: 2460 | G15: 409 | H15: 253 | I15: 36702 | J15: 46122 | K15: 264 | L15: #NowPlaying | N15: =(F15+G15+H15)/I15 -> 0.085063484 | O15: =RANK(N15,$N:$N,0) -> 155 | P15: =F15+G15+H15 -> 3122 | Q15: =IF(AND(--$C15>=--Campaign_Metadata_clean!$B$2,--$C15<=--Campaign_Metadata_clean!$C$2),"SummerBeats", IF(AND(--$C15>=--Campaign_Metadata_clean!$B$3,--$C15<=--Campaign_Metadata_clean!$C$3),"Wrapped2024", IF(AND(--$C15>=--Campaign_Metadata_clean!$B$4,--$C15<=--Campaign_Metadata_clean!$C$4),"ChillVibes", IF(AND(--$C15>=--Campaign_Metadata_clean!$B$5,--$C15<=--Campaign_Metadata_clean!$C$5),"IndieWave","No Campaign")))) -> No Campaign | R15: =IF(AND(C15>=DATE(2025,1,10), C15<=DATE(2025,2,10)), "During", IF(C15<DATE(2025,1,10), "Before", "Other")) -> Before | S15: =IF(OR(X15="",Y15=""),"", IF(AND(C15>=X15-30,C15<X15),"Before", IF(AND(C15>=X15,C15<=Y15),"During","Other"))) | X15: =IFERROR( _xlfn.XLOOKUP(Q15, Campaign_Metadata_clean!A:A, Campaign_Metadata_clean!B:B), "") | Y15: =IFERROR( _xlfn.XLOOKUP(Q15, Campaign_Metadata_clean!A:A, Campaign_Metadata_clean!C:C), "") | Z15: =IFERROR( AVERAGEIFS(N:N, C:C, ">=" & X15-30, C:C, "<" & X15), 0) -> 0 | AA15: =IFERROR( AVERAGEIFS(N:N, C:C, ">=" & X15, C:C, "<=" & Y15), 0) -> 0 | AB15: =IF(AA15=0,0,(AB15-AA15)/AA15) -> 0
A16: SP015 | B16: Twitter | C16: 45418 | D16: Text | E16: Your weekend playlist is waiting. | F16: 3476 | G16: 355 | H16: 396 | I16: 37492 | J16: 27285 | K16: 179 | L16: #NowPlaying | N16: =(F16+G16+H16)/I16 -> 0.11274405 | O16: =RANK(N16,$N:$N,0) -> 75 | P16: =F16+G16+H16 -> 4227 | Q16: =IF(AND(--$C16>=--Campaign_Metadata_clean!$B$2,--$C16<=--Campaign_Metadata_clean!$C$2),"SummerBeats", IF(AND(--$C16>=--Campaign_Metadata_clean!$B$3,--$C16<=--Campaign_Metadata_clean!$C$3),"Wrapped2024", IF(AND(--$C16>=--Campaign_Metadata_clean!$B$4,--$C16<=--Campaign_Metadata_clean!$C$4),"ChillVibes", IF(AND(--$C16>=--Campaign_Metadata_clean!$B$5,--$C16<=--Campaign_Metadata_clean!$C$5),"IndieWave","No Campaign")))) -> No Campaign | R16: =IF(AND(C16>=DATE(2025,1,10), C16<=DATE(2025,2,10)), "During", IF(C16<DATE(2025,1,10), "Before", "Other")) -> Before | S16: =IF(OR(X16="",Y16=""),"", IF(AND(C16>=X16-30,C16<X16),"Before", IF(AND(C16>=X16,C16<=Y16),"During","Other"))) | X16: =IFERROR( _xlfn.XLOOKUP(Q16, Campaign_Metadata_clean!A:A, Campaign_Metadata_clean!B:B), "") | Y16: =IFERROR( _xlfn.XLOOKUP(Q16, Campaign_Metadata_clean!A:A, Campaign_Metadata_clean!C:C), "") | Z16: =IFERROR( AVERAGEIFS(N:N, C:C, ">=" & X16-30, C:C, "<" & X16), 0) -> 0 | AA16: =IFERROR( AVERAGEIFS(N:N, C:C, ">=" & X16, C:C, "<=" & Y16), 0) -> 0 | AB16: =IF(AA16=0,0,(AB16-AA16)/AA16) -> 0
A17: SP016 | B17: Twitter | C17: 45655 | D17: Story | E17: New music just dropped. Hit play! | F17: 4049 | G17: 377 | H17: 94 | I17: 48182 | J17: 42875 | K17: 172 | L17: #MusicForEveryone | M17: #NowPlaying | N17: =(F17+G17+H17)/I17 -> 0.093810967 | O17: =RANK(N17,$N:$N,0) -> 127 | P17: =F17+G17+H17 -> 4520 | Q17: =IF(AND(--$C17>=--Campaign_Metadata_clean!$B$2,--$C17<=--Campaign_Metadata_clean!$C$2),"SummerBeats", IF(AND(--$C17>=--Campaign_Metadata_clean!$B$3,--$C17<=--Campaign_Metadata_clean!$C$3),"Wrapped2024", IF(AND(--$C17>=--Campaign_Metadata_clean!$B$4,--$C17<=--Campaign_Metadata_clean!$C$4),"ChillVibes", IF(AND(--$C17>=--Campaign_Metadata_clean!$B$5,--$C17<=--Campaign_Metadata_clean!$C$5),"IndieWave","No Campaign")))) -> Wrapped2024 | R17: =IF(AND(C17>=DATE(2025,1,10), C17<=DATE(2025,2,10)), "During", IF(C17<DATE(2025,1,10), "Before", "Other")) -> Before | S17: =IF(OR(X17="",Y17=""),"", IF(AND(C17>=X17-30,C17<X17),"Before", IF(AND(C17>=X17,C17<=Y17),"During","Other"))) -> During | X17: =IFERROR( _xlfn.XLOOKUP(Q17, Campaign_Metadata_clean!A:A, Campaign_Metadata_clean!B:B), "") -> 45627 | Y17: =IFERROR( _xlfn.XLOOKUP(Q17, Campaign_Metadata_clean!A:A, Campaign_Metadata_clean!C:C), "") -> 45657 | Z17: =IFERROR( AVERAGEIFS(N:N, C:C, ">=" & X17-30, C:C, "<" & X17), 0) -> 0.092680819 | AA17: =IFERROR( AVERAGEIFS(N:N, C:C, ">=" & X17, C:C, "<=" & Y17), 0) -> 0.099294725 | AB17: =IF(AA17=0,0,(AB17-AA17)/AA17) -> 0
A18: SP017 | B18: Twitter | C18: 45453 | D18: Text | E18: What's your vibe today? #SpotifyHits | F18: 1514 | G18: 164 | H18: 275 | I18: 41364 | J18: 44389 | K18: 83 | L18: #NowPlaying | N18: =(F18+G18+H18)/I18 -> 0.04721497 | O18: =RANK(N18,$N:$N,0) -> 261 | P18: =F18+G18+H18 -> 1953 | Q18: =IF(AND(--$C18>=--Campaign_Metadata_clean!$B$2,--$C18<=--Campaign_Metadata_clean!$C$2),"SummerBeats", IF(AND(--$C18>=--Campaign_Metadata_clean!$B$3,--$C18<=--Campaign_Metadata_clean!$C$3),"Wrapped2024", IF(AND(--$C18>=--Campaign_Metadata_clean!$B$4,--$C18<=--Campaign_Metadata_clean!$C$4),"ChillVibes", IF(AND(--$C18>=--Campaign_Metadata_clean!$B$5,--$C18<=--Campaign_Metadata_clean!$C$5),"IndieWave","No Campaign")))) -> No Campaign | R18: =IF(AND(C18>=DATE(2025,1,10), C18<=DATE(2025,2,10)), "During", IF(C18<DATE(2025,1,10), "Before", "Other")) -> Before | S18: =IF(OR(X18="",Y18=""),"", IF(AND(C18>=X18-30,C18<X18),"Before", IF(AND(C18>=X18,C18<=Y18),"During","Other"))) | X18: =IFERROR( _xlfn.XLOOKUP(Q18, Campaign_Metadata_clean!A:A, Campaign_Metadata_clean!B:B), "") | Y18: =IFERROR( _xlfn.XLOOKUP(Q18, Campaign_Metadata_clean!A:A, Campaign_Metadata_clean!C:C), "") | Z18: =IFERROR( AVERAGEIFS(N:N, C:C, ">=" & X18-30, C:C, "<" & X18), 0) -> 0 | AA18: =IFERROR( AVERAGEIFS(N:N, C:C, ">=" & X18, C:C, "<=" & Y18), 0) -> 0 | AB18: =IF(AA18=0,0,(AB18-AA18)/AA18) -> 0
A19: SP018 | B19: Instagram | C19: 45325 | D19: Story | E19: Music that moves you-only on Spotify. | F19: 4281 | G19: 101 | H19: 163 | I19: 32278 | J19: 53382 | K19: 235 | L19: #NowPlaying | N19: =(F19+G19+H19)/I19 -> 0.14080798 | O19: =RANK(N19,$N:$N,0) -> 46 | P19: =F19+G19+H19 -> 4545 | Q19: =IF(AND(--$C19>=--Campaign_Metadata_clean!$B$2,--$C19<=--Campaign_Metadata_clean!$C$2),"SummerBeats", IF(AND(--$C19>=--Campaign_Metadata_clean!$B$3,--$C19<=--Campaign_Metadata_clean!$C$3),"Wrapped2024", IF(AND(--$C19>=--Campaign_Metadata_clean!$B$4,--$C19<=--Campaign_Metadata_clean!$C$4),"ChillVibes", IF(AND(--$C19>=--Campaign_Metadata_clean!$B$5,--$C19<=--Campaign_Metadata_clean!$C$5),"IndieWave","No Campaign")))) -> No Campaign | R19: =IF(AND(C19>=DATE(2025,1,10), C19<=DATE(2025,2,10)), "During", IF(C19<DATE(2025,1,10), "Before", "Other")) -> Before | S19: =IF(OR(X19="",Y19=""),"", IF(AND(C19>=X19-30,C19<X19),"Before", IF(AND(C19>=X19,C19<=Y19),"During","Other"))) | X19: =IFERROR( _xlfn.XLOOKUP(Q19, Campaign_Metadata_clean!A:A, Campaign_Metadata_clean!B:B), "") | Y19: =IFERROR( _xlfn.XLOOKUP(Q19, Campaign_Metadata_clean!A:A, Campaign_Metadata_clean!C:C), "") | Z19: =IFERROR( AVERAGEIFS(N:N, C:C, ">=" & X19-30, C:C, "<" & X19), 0) -> 0 | AA19: =IFERROR( AVERAGEIFS(N:N, C:C, ">=" & X19, C:C, "<=" & Y19), 0) -> 0 | AB19: =IF(AA19=0,0,(AB19-AA19)/AA19) -> 0
A20: SP019 | B20: YouTube | C20: 45458 | D20: Reel | E20: Get into the groove with our new drop! | F20: 1751 | G20: 143 | H20: 151 | I20: 31826 | J20: 47729 | K20: 95 | L20: #DiscoverWeekly | M20: #SoundtrackOfLife | N20: =(F20+G20+H20)/I20 -> 0.06425564 | O20: =RANK(N20,$N:$N,0) -> 213 | P20: =F20+G20+H20 -> 2045 | Q20: =IF(AND(--$C20>=--Campaign_Metadata_clean!$B$2,--$C20<=--Campaign_Metadata_clean!$C$2),"SummerBeats", IF(AND(--$C20>=--Campaign_Metadata_clean!$B$3,--$C20<=--Campaign_Metadata_clean!$C$3),"Wrapped2024", IF(AND(--$C20>=--Campaign_Metadata_clean!$B$4,--$C20<=--Campaign_Metadata_clean!$C$4),"ChillVibes", IF(AND(--$C20>=--Campaign_Metadata_clean!$B$5,--$C20<=--Campaign_Metadata_clean!$C$5),"IndieWave","No Campaign")))) -> SummerBeats | R20: =IF(AND(C20>=DATE(2025,1,10), C20<=DATE(2025,2,10)), "During", IF(C20<DATE(2025,1,10), "Before", "Other")) -> Before | S20: =IF(OR(X20="",Y20=""),"", IF(AND(C20>=X20-30,C20<X20),"Before", IF(AND(C20>=X20,C20<=Y20),"During","Other"))) -> During | X20: =IFERROR( _xlfn.XLOOKUP(Q20, Campaign_Metadata_clean!A:A, Campaign_Metadata_clean!B:B), "") -> 45458 | Y20: =IFERROR( _xlfn.XLOOKUP(Q20, Campaign_Metadata_clean!A:A, Campaign_Metadata_clean!C:C), "") -> 45488 | Z20: =IFERROR( AVERAGEIFS(N:N, C:C, ">=" & X20-30, C:C, "<" & X20), 0) -> 0.077477552 | AA20: =IFERROR( AVERAGEIFS(N:N, C:C, ">=" & X20, C:C, "<=" & Y20), 0) -> 0.096749506 | AB20: =IF(AA20=0,0,(AB20-AA20)/AA20) -> 0
A21: SP020 | B21: Instagram | C21: 45478 | D21: Text | E21: Your weekend playlist is waiting. | F21: 3753 | G21: 411 | H21: 308 | I21: 29138 | J21: 27678 | K21: 90 | L21: #DiscoverWeekly | N21: =(F21+G21+H21)/I21 -> 0.15347656 | O21: =RANK(N21,$N:$N,0) -> 35 | P21: =F21+G21+H21 -> 4472 | Q21: =IF(AND(--$C21>=--Campaign_Metadata_clean!$B$2,--$C21<=--Campaign_Metadata_clean!$C$2),"SummerBeats", IF(AND(--$C21>=--Campaign_Metadata_clean!$B$3,--$C21<=--Campaign_Metadata_clean!$C$3),"Wrapped2024", IF(AND(--$C21>=--Campaign_Metadata_clean!$B$4,--$C21<=--Campaign_Metadata_clean!$C$4),"ChillVibes", IF(AND(--$C21>=--Campaign_Metadata_clean!$B$5,--$C21<=--Campaign_Metadata_clean!$C$5),"IndieWave","No Campaign")))) -> SummerBeats | R21: =IF(AND(C21>=DATE(2025,1,10), C21<=DATE(2025,2,10)), "During", IF(C21<DATE(2025,1,10), "Before", "Other")) -> Before | S21: =IF(OR(X21="",Y21=""),"", IF(AND(C21>=X21-30,C21<X21),"Before", IF(AND(C21>=X21,C21<=Y21),"During","Other"))) -> During | X21: =IFERROR( _xlfn.XLOOKUP(Q21, Campaign_Metadata_clean!A:A, Campaign_Metadata_clean!B:B), "") -> 45458 | Y21: =IFERROR( _xlfn.XLOOKUP(Q21, Campaign_Metadata_clean!A:A, Campaign_Metadata_clean!C:C), "") -> 45488 | Z21: =IFERROR( AVERAGEIFS(N:N, C:C, ">=" & X21-30, C:C, "<" & X21), 0) -> 0.077477552 | AA21: =IFERROR( AVERAGEIFS(N:N, C:C, ">=" & X21, C:C, "<=" & Y21), 0) -> 0.096749506 | AB21: =IF(AA21=0,0,(AB21-AA21)/AA21) -> 0
A22: SP021 | B22: Instagram | C22: 45603 | D22: Story | E22: Wrapped is here! Relive your top tracks | F22: 1678 | G22: 423 | H22: 323 | I22: 55668 | J22: 37945 | K22: 230 | L22: #NowPlaying | N22: =(F22+G22+H22)/I22 -> 0.043543867 | O22: =RANK(N22,$N:$N,0) -> 271 | P22: =F22+G22+H22 -> 2424 | Q22: =IF(AND(--$C22>=--Campaign_Metadata_clean!$B$2,--$C22<=--Campaign_Metadata_clean!$C$2),"SummerBeats", IF(AND(--$C22>=--Campaign_Metadata_clean!$B$3,--$C22<=--Campaign_Metadata_clean!$C$3),"Wrapped2024", IF(AND(--$C22>=--Campaign_Metadata_clean!$B$4,--$C22<=--Campaign_Metadata_clean!$C$4),"ChillVibes", IF(AND(--$C22>=--Campaign_Metadata_clean!$B$5,--$C22<=--Campaign_Metadata_clean!$C$5),"IndieWave","No Campaign")))) -> No Campaign | R22: =IF(AND(C22>=DATE(2025,1,10), C22<=DATE(2025,2,10)), "During", IF(C22<DATE(2025,1,10), "Before", "Other")) -> Before | S22: =IF(OR(X22="",Y22=""),"", IF(AND(C22>=X22-30,C22<X22),"Before", IF(AND(C22>=X22,C22<=Y22),"During","Other"))) | X22: =IFERROR( _xlfn.XLOOKUP(Q22, Campaign_Metadata_clean!A:A, Campaign_Metadata_clean!B:B), "") | Y22: =IFERROR( _xlfn.XLOOKUP(Q22, Campaign_Metadata_clean!A:A, Campaign_Metadata_clean!C:C), "") | Z22: =IFERROR( AVERAGEIFS(N:N, C:C, ">=" & X22-30, C:C, "<" & X22), 0) -> 0 | AA22: =IFERROR( AVERAGEIFS(N:N, C:C, ">=" & X22, C:C, "<=" & Y22), 0) -> 0 | AB22: =IF(AA22=0,0,(AB22-AA22)/AA22) -> 0
A23: SP022 | B23: Instagram | C23: 45823 | D23: Text | E23: What's your vibe today? #SpotifyHits | F23: 4896 | G23: 466 | H23: 233 | I23: 28621 | J23: 34270 | K23: 84 | L23: #SoundtrackOfLife | M23: #NowPlaying | N23: =(F23+G23+H23)/I23 -> 0.19548583 | O23: =RANK(N23,$N:$N,0) -> 6 | P23: =F23+G23+H23 -> 5595 | Q23: =IF(AND(--$C23>=--Campaign_Metadata_clean!$B$2,--$C23<=--Campaign_Metadata_clean!$C$2),"SummerBeats", IF(AND(--$C23>=--Campaign_Metadata_clean!$B$3,--$C23<=--Campaign_Metadata_clean!$C$3),"Wrapped2024", IF(AND(--$C23>=--Campaign_Metadata_clean!$B$4,--$C23<=--Campaign_Metadata_clean!$C$4),"ChillVibes", IF(AND(--$C23>=--Campaign_Metadata_clean!$B$5,--$C23<=--Campaign_Metadata_clean!$C$5),"IndieWave","No Campaign")))) -> No Campaign | R23: =IF(AND(C23>=DATE(2025,1,10), C23<=DATE(2025,2,10)), "During", IF(C23<DATE(2025,1,10), "Before", "Other")) -> Other | S23: =IF(OR(X23="",Y23=""),"", IF(AND(C23>=X23-30,C23<X23),"Before", IF(AND(C23>=X23,C23<=Y23),"During","Other"))) | X23: =IFERROR( _xlfn.XLOOKUP(Q23, Campaign_Metadata_clean!A:A, Campaign_Metadata_clean!B:B), "") | Y23: =IFERROR( _xlfn.XLOOKUP(Q23, Campaign_Metadata_clean!A:A, Campaign_Metadata_clean!C:C), "") | Z23: =IFERROR( AVERAGEIFS(N:N, C:C, ">=" & X23-30, C:C, "<" & X23), 0) -> 0 | AA23: =IFERROR( AVERAGEIFS(N:N, C:C, ">=" & X23, C:C, "<=" & Y23), 0) -> 0 | AB23: =IF(AA23=0,0,(AB23-AA23)/AA23) -> 0
A24: SP023 | B24: YouTube | C24: 45452 | D24: Reel | E24: From pop to podcasts, it's all here. | F24: 2786 | G24: 368 | H24: 208 | I24: 42000 | J24: 39967 | K24: 103 | L24: #DiscoverWeekly | M24: #SoundtrackOfLife | N24: =(F24+G24+H24)/I24 -> 0.080047619 | O24: =RANK(N24,$N:$N,0) -> 178 | P24: =F24+G24+H24 -> 3362 | Q24: =IF(AND(--$C24>=--Campaign_Metadata_clean!$B$2,--$C24<=--Campaign_Metadata_clean!$C$2),"SummerBeats", IF(AND(--$C24>=--Campaign_Metadata_clean!$B$3,--$C24<=--Campaign_Metadata_clean!$C$3),"Wrapped2024", IF(AND(--$C24>=--Campaign_Metadata_clean!$B$4,--$C24<=--Campaign_Metadata_clean!$C$4),"ChillVibes", IF(AND(--$C24>=--Campaign_Metadata_clean!$B$5,--$C24<=--Campaign_Metadata_clean!$C$5),"IndieWave","No Campaign")))) -> No Campaign | R24: =IF(AND(C24>=DATE(2025,1,10), C24<=DATE(2025,2,10)), "During", IF(C24<DATE(2025,1,10), "Before", "Other")) -> Before | S24: =IF(OR(X24="",Y24=""),"", IF(AND(C24>=X24-30,C24<X24),"Before", IF(AND(C24>=X24,C24<=Y24),"During","Other"))) | X24: =IFERROR( _xlfn.XLOOKUP(Q24, Campaign_Metadata_clean!A:A, Campaign_Metadata_clean!B:B), "") | Y24: =IFERROR( _xlfn.XLOOKUP(Q24, Campaign_Metadata_clean!A:A, Campaign_Metadata_clean!C:C), "") | Z24: =IFERROR( AVERAGEIFS(N:N, C:C, ">=" & X24-30, C:C, "<" & X24), 0) -> 0 | AA24: =IFERROR( AVERAGEIFS(N:N, C:C, ">=" & X24, C:C, "<=" & Y24), 0) -> 0 | AB24: =IF(AA24=0,0,(AB24-AA24)/AA24) -> 0
A25: SP024 | B25: Twitter | C25: 45583 | D25: Text | E25: New music just dropped. Hit play! | F25: 2607 | G25: 379 | H25: 180 | I25: 28712 | J25: 61620 | K25: 174 | L25: #SoundtrackOfLife | N25: =(F25+G25+H25)/I25 -> 0.11026748 | O25: =RANK(N25,$N:$N,0) -> 83 | P25: =F25+G25+H25 -> 3166 | Q25: =IF(AND(--$C25>=--Campaign_Metadata_clean!$B$2,--$C25<=--Campaign_Metadata_clean!$C$2),"SummerBeats", IF(AND(--$C25>=--Campaign_Metadata_clean!$B$3,--$C25<=--Campaign_Metadata_clean!$C$3),"Wrapped2024", IF(AND(--$C25>=--Campaign_Metadata_clean!$B$4,--$C25<=--Campaign_Metadata_clean!$C$4),"ChillVibes", IF(AND(--$C25>=--Campaign_Metadata_clean!$B$5,--$C25<=--Campaign_Metadata_clean!$C$5),"IndieWave","No Campaign")))) -> No Campaign | R25: =IF(AND(C25>=DATE(2025,1,10), C25<=DATE(2025,2,10)), "During", IF(C25<DATE(2025,1,10), "Before", "Other")) -> Before | S25: =IF(OR(X25="",Y25=""),"", IF(AND(C25>=X25-30,C25<X25),"Before", IF(AND(C25>=X25,C25<=Y25),"During","Other"))) | X25: =IFERROR( _xlfn.XLOOKUP(Q25, Campaign_Metadata_clean!A:A, Campaign_Metadata_clean!B:B), "") | Y25: =IFERROR( _xlfn.XLOOKUP(Q25, Campaign_Metadata_clean!A:A, Campaign_Metadata_clean!C:C), "") | Z25: =IFERROR( AVERAGEIFS(N:N, C:C, ">=" & X25-30, C:C, "<" & X25), 0) -> 0 | AA25: =IFERROR( AVERAGEIFS(N:N, C:C, ">=" & X25, C:C, "<=" & Y25), 0) -> 0 | AB25: =IF(AA25=0,0,(AB25-AA25)/AA25) -> 0
A26: SP025 | B26: YouTube | C26: 45575 | D26: Reel | E26: From pop to podcasts, it's all here. | F26: 4013 | G26: 320 | H26: 92 | I26: 54605 | J26: 60169 | K26: 232 | L26: #DiscoverWeekly | M26: #SoundtrackOfLife | N26: =(F26+G26+H26)/I26 -> 0.081036535 | O26: =RANK(N26,$N:$N,0) -> 174 | P26: =F26+G26+H26 -> 4425 | Q26: =IF(AND(--$C26>=--Campaign_Metadata_clean!$B$2,--$C26<=--Campaign_Metadata_clean!$C$2),"SummerBeats", IF(AND(--$C26>=--Campaign_Metadata_clean!$B$3,--$C26<=--Campaign_Metadata_clean!$C$3),"Wrapped2024", IF(AND(--$C26>=--Campaign_Metadata_clean!$B$4,--$C26<=--Campaign_Metadata_clean!$C$4),"ChillVibes", IF(AND(--$C26>=--Campaign_Metadata_clean!$B$5,--$C26<=--Campaign_Metadata_clean!$C$5),"IndieWave","No Campaign")))) -> No Campaign | R26: =IF(AND(C26>=DATE(2025,1,10), C26<=DATE(2025,2,10)), "During", IF(C26<DATE(2025,1,10), "Before", "Other")) -> Before | S26: =IF(OR(X26="",Y26=""),"", IF(AND(C26>=X26-30,C26<X26),"Before", IF(AND(C26>=X26,C26<=Y26),"During","Other"))) | X26: =IFERROR( _xlfn.XLOOKUP(Q26, Campaign_Metadata_clean!A:A, Campaign_Metadata_clean!B:B), "") | Y26: =IFERROR( _xlfn.XLOOKUP(Q26, Campaign_Metadata_clean!A:A, Campaign_Metadata_clean!C:C), "") | Z26: =IFERROR( AVERAGEIFS(N:N, C:C, ">=" & X26-30, C:C, "<" & X26), 0) -> 0 | AA26: =IFERROR( AVERAGEIFS(N:N, C:C, ">=" & X26, C:C, "<=" & Y26), 0) -> 0 | AB26: =IF(AA26=0,0,(AB26-AA26)/AA26) -> 0
A27: SP026 | B27: Twitter | C27: 45791 | D27: Story | E27: From pop to podcasts, it's all here. | F27: 2707 | G27: 103 | H27: 51 | I27: 55302 | J27: 18801 | K27: 147 | L27: #DiscoverWeekly | M27: #MusicForEveryone | N27: =(F27+G27+H27)/I27 -> 0.051734114 | O27: =RANK(N27,$N:$N,0) -> 251 | P27: =F27+G27+H27 -> 2861 | Q27: =IF(AND(--$C27>=--Campaign_Metadata_clean!$B$2,--$C27<=--Campaign_Metadata_clean!$C$2),"SummerBeats", IF(AND(--$C27>=--Campaign_Metadata_clean!$B$3,--$C27<=--Campaign_Metadata_clean!$C$3),"Wrapped2024", IF(AND(--$C27>=--Campaign_Metadata_clean!$B$4,--$C27<=--Campaign_Metadata_clean!$C$4),"ChillVibes", IF(AND(--$C27>=--Campaign_Metadata_clean!$B$5,--$C27<=--Campaign_Metadata_clean!$C$5),"IndieWave","No Campaign")))) -> No Campaign | R27: =IF(AND(C27>=DATE(2025,1,10), C27<=DATE(2025,2,10)), "During", IF(C27<DATE(2025,1,10), "Before", "Other")) -> Other | S27: =IF(OR(X27="",Y27=""),"", IF(AND(C27>=X27-30,C27<X27),"Before", IF(AND(C27>=X27,C27<=Y27),"During","Other"))) | X27: =IFERROR( _xlfn.XLOOKUP(Q27, Campaign_Metadata_clean!A:A, Campaign_Metadata_clean!B:B), "") | Y27: =IFERROR( _xlfn.XLOOKUP(Q27, Campaign_Metadata_clean!A:A, Campaign_Metadata_clean!C:C), "") | Z27: =IFERROR( AVERAGEIFS(N:N, C:C, ">=" & X27-30, C:C, "<" & X27), 0) -> 0 | AA27: =IFERROR( AVERAGEIFS(N:N, C:C, ">=" & X27, C:C, "<=" & Y27), 0) -> 0 | AB27: =IF(AA27=0,0,(AB27-AA27)/AA27) -> 0
A28: SP027 | B28: Instagram | C28: 45625 | D28: Text | E28: What's your vibe today? #SpotifyHits | F28: 2824 | G28: 425 | H28: 274 | I28: 31004 | J28: 53488 | K28: 268 | L28: #SoundtrackOfLife | M28: #NowPlaying | N28: =(F28+G28+H28)/I28 -> 0.1136305 | O28: =RANK(N28,$N:$N,0) -> 73 | P28: =F28+G28+H28 -> 3523 | Q28: =IF(AND(--$C28>=--Campaign_Metadata_clean!$B$2,--$C28<=--Campaign_Metadata_clean!$C$2),"SummerBeats", IF(AND(--$C28>=--Campaign_Metadata_clean!$B$3,--$C28<=--Campaign_Metadata_clean!$C$3),"Wrapped2024", IF(AND(--$C28>=--Campaign_Metadata_clean!$B$4,--$C28<=--Campaign_Metadata_clean!$C$4),"ChillVibes", IF(AND(--$C28>=--Campaign_Metadata_clean!$B$5,--$C28<=--Campaign_Metadata_clean!$C$5),"IndieWave","No Campaign")))) -> No Campaign | R28: =IF(AND(C28>=DATE(2025,1,10), C28<=DATE(2025,2,10)), "During", IF(C28<DATE(2025,1,10), "Before", "Other")) -> Before | S28: =IF(OR(X28="",Y28=""),"", IF(AND(C28>=X28-30,C28<X28),"Before", IF(AND(C28>=X28,C28<=Y28),"During","Other"))) | X28: =IFERROR( _xlfn.XLOOKUP(Q28, Campaign_Metadata_clean!A:A, Campaign_Metadata_clean!B:B), "") | Y28: =IFERROR( _xlfn.XLOOKUP(Q28, Campaign_Metadata_clean!A:A, Campaign_Metadata_clean!C:C), "") | Z28: =IFERROR( AVERAGEIFS(N:N, C:C, ">=" & X28-30, C:C, "<" & X28), 0) -> 0 | AA28: =IFERROR( AVERAGEIFS(N:N, C:C, ">=" & X28, C:C, "<=" & Y28), 0) -> 0 | AB28: =IF(AA28=0,0,(AB28-AA28)/AA28) -> 0
A29: SP028 | B29: YouTube | C29: 45356 | D29: Reel | E29: Explore the latest podcasts now. | F29: 3558 | G29: 314 | H29: 199 | I29: 49612 | J29: 53929 | K29: 206 | L29: #DiscoverWeekly | M29: #SoundtrackOfLife | N29: =(F29+G29+H29)/I29 -> 0.08205676 | O29: =RANK(N29,$N:$N,0) -> 169 | P29: =F29+G29+H29 -> 4071 | Q29: =IF(AND(--$C29>=--Campaign_Metadata_clean!$B$2,--$C29<=--Campaign_Metadata_clean!$C$2),"SummerBeats", IF(AND(--$C29>=--Campaign_Metadata_clean!$B$3,--$C29<=--Campaign_Metadata_clean!$C$3),"Wrapped2024", IF(AND(--$C29>=--Campaign_Metadata_clean!$B$4,--$C29<=--Campaign_Metadata_clean!$C$4),"ChillVibes", IF(AND(--$C29>=--Campaign_Metadata_clean!$B$5,--$C29<=--Campaign_Metadata_clean!$C$5),"IndieWave","No Campaign")))) -> No Campaign | R29: =IF(AND(C29>=DATE(2025,1,10), C29<=DATE(2025,2,10)), "During", IF(C29<DATE(2025,1,10), "Before", "Other")) -> Before | S29: =IF(OR(X29="",Y29=""),"", IF(AND(C29>=X29-30,C29<X29),"Before", IF(AND(C29>=X29,C29<=Y29),"During","Other"))) | X29: =IFERROR( _xlfn.XLOOKUP(Q29, Campaign_Metadata_clean!A:A, Campaign_Metadata_clean!B:B), "") | Y29: =IFERROR( _xlfn.XLOOKUP(Q29, Campaign_Metadata_clean!A:A, Campaign_Metadata_clean!C:C), "") | Z29: =IFERROR( AVERAGEIFS(N:N, C:C, ">=" & X29-30, C:C, "<" & X29), 0) -> 0 | AA29: =IFERROR( AVERAGEIFS(N:N, C:C, ">=" & X29, C:C, "<=" & Y29), 0) -> 0 | AB29: =IF(AA29=0,0,(AB29-AA29)/AA29) -> 0
A30: SP029 | B30: Twitter | C30: 45734 | D30: Story | E30: Explore the latest podcasts now. | F30: 3418 | G30: 188 | H30: 387 | I30: 57431 | J30: 36933 | K30: 202 | L30: #MusicForEveryone | M30: #NowPlaying | N30: =(F30+G30+H30)/I30 -> 0.069526911 | O30: =RANK(N30,$N:$N,0) -> 203 | P30: =F30+G30+H30 -> 3993 | Q30: =IF(AND(--$C30>=--Campaign_Metadata_clean!$B$2,--$C30<=--Campaign_Metadata_clean!$C$2),"SummerBeats", IF(AND(--$C30>=--Campaign_Metadata_clean!$B$3,--$C30<=--Campaign_Metadata_clean!$C$3),"Wrapped2024", IF(AND(--$C30>=--Campaign_Metadata_clean!$B$4,--$C30<=--Campaign_Metadata_clean!$C$4),"ChillVibes", IF(AND(--$C30>=--Campaign_Metadata_clean!$B$5,--$C30<=--Campaign_Metadata_clean!$C$5),"IndieWave","No Campaign")))) -> IndieWave | R30: =IF(AND(C30>=DATE(2025,1,10), C30<=DATE(2025,2,10)), "During", IF(C30<DATE(2025,1,10), "Before", "Other")) -> Other | S30: =IF(OR(X30="",Y30=""),"", IF(AND(C30>=X30-30,C30<X30),"Before", IF(AND(C30>=X30,C30<=Y30),"During","Other"))) -> During | X30: =IFERROR( _xlfn.XLOOKUP(Q30, Campaign_Metadata_clean!A:A, Campaign_Metadata_clean!B:B), "") -> 45717 | Y30: =IFERROR( _xlfn.XLOOKUP(Q30, Campaign_Metadata_clean!A:A, Campaign_Metadata_clean!C:C), "") -> 45747 | Z30: =IFERROR( AVERAGEIFS(N:N, C:C, ">=" & X30-30, C:C, "<" & X30), 0) -> 0.11058335 | AA30: =IFERROR( AVERAGEIFS(N:N, C:C, ">=" & X30, C:C, "<=" & Y30), 0) -> 0.10264546 | AB30: =IF(AA30=0,0,(AB30-AA30)/AA30) -> 0
A31: SP030 | B31: Twitter | C31: 45773 | D31: Text | E31: Discover fresh beats on Spotify! | F31: 2411 | G31: 194 | H31: 168 | I31: 26665 | J31: 71699 | K31: 197 | L31: #NowPlaying | N31: =(F31+G31+H31)/I31 -> 0.103994 | O31: =RANK(N31,$N:$N,0) -> 101 | P31: =F31+G31+H31 -> 2773 | Q31: =IF(AND(--$C31>=--Campaign_Metadata_clean!$B$2,--$C31<=--Campaign_Metadata_clean!$C$2),"SummerBeats", IF(AND(--$C31>=--Campaign_Metadata_clean!$B$3,--$C31<=--Campaign_Metadata_clean!$C$3),"Wrapped2024", IF(AND(--$C31>=--Campaign_Metadata_clean!$B$4,--$C31<=--Campaign_Metadata_clean!$C$4),"ChillVibes", IF(AND(--$C31>=--Campaign_Metadata_clean!$B$5,--$C31<=--Campaign_Metadata_clean!$C$5),"IndieWave","No Campaign")))) -> No Campaign | R31: =IF(AND(C31>=DATE(2025,1,10), C31<=DATE(2025,2,10)), "During", IF(C31<DATE(2025,1,10), "Before", "Other")) -> Other | S31: =IF(OR(X31="",Y31=""),"", IF(AND(C31>=X31-30,C31<X31),"Before", IF(AND(C31>=X31,C31<=Y31),"During","Other"))) | X31: =IFERROR( _xlfn.XLOOKUP(Q31, Campaign_Metadata_clean!A:A, Campaign_Metadata_clean!B:B), "") | Y31: =IFERROR( _xlfn.XLOOKUP(Q31, Campaign_Metadata_clean!A:A, Campaign_Metadata_clean!C:C), "") | Z31: =IFERROR( AVERAGEIFS(N:N, C:C, ">=" & X31-30, C:C, "<" & X31), 0) -> 0 | AA31: =IFERROR( AVERAGEIFS(N:N, C:C, ">=" & X31, C:C, "<=" & Y31), 0) -> 0 | AB31: =IF(AA31=0,0,(AB31-AA31)/AA31) -> 0
A32: SP031 | B32: Instagram | C32: 45658 | D32: Text | E32: New music just dropped. Hit play! | F32: 4036 | G32: 112 | H32: 382 | I32: 56284 | J32: 29440 | K32: 279 | L32: #SoundtrackOfLife | M32: #NowPlaying | N32: =(F32+G32+H32)/I32 -> 0.080484685 | O32: =RANK(N32,$N:$N,0) -> 176 | P32: =F32+G32+H32 -> 4530 | Q32: =IF(AND(--$C32>=--Campaign_Metadata_clean!$B$2,--$C32<=--Campaign_Metadata_clean!$C$2),"SummerBeats", IF(AND(--$C32>=--Campaign_Metadata_clean!$B$3,--$C32<=--Campaign_Metadata_clean!$C$3),"Wrapped2024", IF(AND(--$C32>=--Campaign_Metadata_clean!$B$4,--$C32<=--Campaign_Metadata_clean!$C$4),"ChillVibes", IF(AND(--$C32>=--Campaign_Metadata_clean!$B$5,--$C32<=--Campaign_Metadata_clean!$C$5),"IndieWave","No Campaign")))) -> No Campaign | R32: =IF(AND(C32>=DATE(2025,1,10), C32<=DATE(2025,2,10)), "During", IF(C32<DATE(2025,1,10), "Before", "Other")) -> Before | S32: =IF(OR(X32="",Y32=""),"", IF(AND(C32>=X32-30,C32<X32),"Before", IF(AND(C32>=X32,C32<=Y32),"During","Other"))) | X32: =IFERROR( _xlfn.XLOOKUP(Q32, Campaign_Metadata_clean!A:A, Campaign_Metadata_clean!B:B), "") | Y32: =IFERROR( _xlfn.XLOOKUP(Q32, Campaign_Metadata_clean!A:A, Campaign_Metadata_clean!C:C), "") | Z32: =IFERROR( AVERAGEIFS(N:N, C:C, ">=" & X32-30, C:C, "<" & X32), 0) -> 0 | AA32: =IFERROR( AVERAGEIFS(N:N, C:C, ">=" & X32, C:C, "<=" & Y32), 0) -> 0 | AB32: =IF(AA32=0,0,(AB32-AA32)/AA32) -> 0
A33: SP032 | B33: Twitter | C33: 45419 | D33: Story | E33: Explore the latest podcasts now. | F33: 2776 | G33: 307 | H33: 178 | I33: 43365 | J33: 48408 | K33: 138 | L33: #SoundtrackOfLife | M33: #NowPlaying | N33: =(F33+G33+H33)/I33 -> 0.075198893 | O33: =RANK(N33,$N:$N,0) -> 187 | P33: =F33+G33+H33 -> 3261 | Q33: =IF(AND(--$C33>=--Campaign_Metadata_clean!$B$2,--$C33<=--Campaign_Metadata_clean!$C$2),"SummerBeats", IF(AND(--$C33>=--Campaign_Metadata_clean!$B$3,--$C33<=--Campaign_Metadata_clean!$C$3),"Wrapped2024", IF(AND(--$C33>=--Campaign_Metadata_clean!$B$4,--$C33<=--Campaign_Metadata_clean!$C$4),"ChillVibes", IF(AND(--$C33>=--Campaign_Metadata_clean!$B$5,--$C33<=--Campaign_Metadata_clean!$C$5),"IndieWave","No Campaign")))) -> No Campaign | R33: =IF(AND(C33>=DATE(2025,1,10), C33<=DATE(2025,2,10)), "During", IF(C33<DATE(2025,1,10), "Before", "Other")) -> Before | S33: =IF(OR(X33="",Y33=""),"", IF(AND(C33>=X33-30,C33<X33),"Before", IF(AND(C33>=X33,C33<=Y33),"During","Other"))) | X33: =IFERROR( _xlfn.XLOOKUP(Q33, Campaign_Metadata_clean!A:A, Campaign_Metadata_clean!B:B), "") | Y33: =IFERROR( _xlfn.XLOOKUP(Q33, Campaign_Metadata_clean!A:A, Campaign_Metadata_clean!C:C), "") | Z33: =IFERROR( AVERAGEIFS(N:N, C:C, ">=" & X33-30, C:C, "<" & X33), 0) -> 0 | AA33: =IFERROR( AVERAGEIFS(N:N, C:C, ">=" & X33, C:C, "<=" & Y33), 0) -> 0 | AB33: =IF(AA33=0,0,(AB33-AA33)/AA33) -> 0
A34: SP033 | B34: Twitter | C34: 45574 | D34: Story | E34: Discover fresh beats on Spotify! | F34: 4929 | G34: 182 | H34: 95 | I34: 32181 | J34: 31084 | K34: 289 | L34: #DiscoverWeekly | M34: #MusicForEveryone | N34: =(F34+G34+H34)/I34 -> 0.16177247 | O34: =RANK(N34,$N:$N,0) -> 25 | P34: =F34+G34+H34 -> 5206 | Q34: =IF(AND(--$C34>=--Campaign_Metadata_clean!$B$2,--$C34<=--Campaign_Metadata_clean!$C$2),"SummerBeats", IF(AND(--$C34>=--Campaign_Metadata_clean!$B$3,--$C34<=--Campaign_Metadata_clean!$C$3),"Wrapped2024", IF(AND(--$C34>=--Campaign_Metadata_clean!$B$4,--$C34<=--Campaign_Metadata_clean!$C$4),"ChillVibes", IF(AND(--$C34>=--Campaign_Metadata_clean!$B$5,--$C34<=--Campaign_Metadata_clean!$C$5),"IndieWave","No Campaign")))) -> No Campaign | R34: =IF(AND(C34>=DATE(2025,1,10), C34<=DATE(2025,2,10)), "During", IF(C34<DATE(2025,1,10), "Before", "Other")) -> Before | S34: =IF(OR(X34="",Y34=""),"", IF(AND(C34>=X34-30,C34<X34),"Before", IF(AND(C34>=X34,C34<=Y34),"During","Other"))) | X34: =IFERROR( _xlfn.XLOOKUP(Q34, Campaign_Metadata_clean!A:A, Campaign_Metadata_clean!B:B), "") | Y34: =IFERROR( _xlfn.XLOOKUP(Q34, Campaign_Metadata_clean!A:A, Campaign_Metadata_clean!C:C), "") | Z34: =IFERROR( AVERAGEIFS(N:N, C:C, ">=" & X34-30, C:C, "<" & X34), 0) -> 0 | AA34: =IFERROR( AVERAGEIFS(N:N, C:C, ">=" & X34, C:C, "<=" & Y34), 0) -> 0 | AB34: =IF(AA34=0,0,(AB34-AA34)/AA34) -> 0
A35: SP034 | B35: Instagram | C35: 45666 | D35: Text | E35: New music just dropped. Hit play! | F35: 1015 | G35: 366 | H35: 308 | I35: 38127 | J35: 63790 | K35: 287 | L35: #SoundtrackOfLife | M35: #NowPlaying | N35: =(F35+G35+H35)/I35 -> 0.044299315 | O35: =RANK(N35,$N:$N,0) -> 268 | P35: =F35+G35+H35 -> 1689 | Q35: =IF(AND(--$C35>=--Campaign_Metadata_clean!$B$2,--$C35<=--Campaign_Metadata_clean!$C$2),"SummerBeats", IF(AND(--$C35>=--Campaign_Metadata_clean!$B$3,--$C35<=--Campaign_Metadata_clean!$C$3),"Wrapped2024", IF(AND(--$C35>=--Campaign_Metadata_clean!$B$4,--$C35<=--Campaign_Metadata_clean!$C$4),"ChillVibes", IF(AND(--$C35>=--Campaign_Metadata_clean!$B$5,--$C35<=--Campaign_Metadata_clean!$C$5),"IndieWave","No Campaign")))) -> No Campaign | R35: =IF(AND(C35>=DATE(2025,1,10), C35<=DATE(2025,2,10)), "During", IF(C35<DATE(2025,1,10), "Before", "Other")) -> Before | S35: =IF(OR(X35="",Y35=""),"", IF(AND(C35>=X35-30,C35<X35),"Before", IF(AND(C35>=X35,C35<=Y35),"During","Other"))) | X35: =IFERROR( _xlfn.XLOOKUP(Q35, Campaign_Metadata_clean!A:A, Campaign_Metadata_clean!B:B), "") | Y35: =IFERROR( _xlfn.XLOOKUP(Q35, Campaign_Metadata_clean!A:A, Campaign_Metadata_clean!C:C), "") | Z35: =IFERROR( AVERAGEIFS(N:N, C:C, ">=" & X35-30, C:C, "<" & X35), 0) -> 0 | AA35: =IFERROR( AVERAGEIFS(N:N, C:C, ">=" & X35, C:C, "<=" & Y35), 0) -> 0 | AB35: =IF(AA35=0,0,(AB35-AA35)/AA35) -> 0
A36: SP035 | B36: Twitter | C36: 45785 | D36: Story | E36: Your weekend playlist is waiting. | F36: 3316 | G36: 332 | H36: 268 | I36: 40095 | J36: 36913 | K36: 265 | L36: #MusicForEveryone | M36: #NowPlaying | N36: =(F36+G36+H36)/I36 -> 0.097668038 | O36: =RANK(N36,$N:$N,0) -> 116 | P36: =F36+G36+H36 -> 3916 | Q36: =IF(AND(--$C36>=--Campaign_Metadata_clean!$B$2,--$C36<=--Campaign_Metadata_clean!$C$2),"SummerBeats", IF(AND(--$C36>=--Campaign_Metadata_clean!$B$3,--$C36<=--Campaign_Metadata_clean!$C$3),"Wrapped2024", IF(AND(--$C36>=--Campaign_Metadata_clean!$B$4,--$C36<=--Campaign_Metadata_clean!$C$4),"ChillVibes", IF(AND(--$C36>=--Campaign_Metadata_clean!$B$5,--$C36<=--Campaign_Metadata_clean!$C$5),"IndieWave","No Campaign")))) -> No Campaign | R36: =IF(AND(C36>=DATE(2025,1,10), C36<=DATE(2025,2,10)), "During", IF(C36<DATE(2025,1,10), "Before", "Other")) -> Other | S36: =IF(OR(X36="",Y36=""),"", IF(AND(C36>=X36-30,C36<X36),"Before", IF(AND(C36>=X36,C36<=Y36),"During","Other"))) | X36: =IFERROR( _xlfn.XLOOKUP(Q36, Campaign_Metadata_clean!A:A, Campaign_Metadata_clean!B:B), "") | Y36: =IFERROR( _xlfn.XLOOKUP(Q36, Campaign_Metadata_clean!A:A, Campaign_Metadata_clean!C:C), "") | Z36: =IFERROR( AVERAGEIFS(N:N, C:C, ">=" & X36-30, C:C, "<" & X36), 0) -> 0 | AA36: =IFERROR( AVERAGEIFS(N:N, C:C, ">=" & X36, C:C, "<=" & Y36), 0) -> 0 | AB36: =IF(AA36=0,0,(AB36-AA36)/AA36) -> 0
A37: SP036 | B37: Instagram | C37: 45416 | D37: Text | E37: Wrapped is here! Relive your top tracks | F37: 2274 | G37: 243 | H37: 222 | I37: 43066 | J37: 59174 | K37: 80 | L37: #DiscoverWeekly | N37: =(F37+G37+H37)/I37 -> 0.063600056 | O37: =RANK(N37,$N:$N,0) -> 215 | P37: =F37+G37+H37 -> 2739 | Q37: =IF(AND(--$C37>=--Campaign_Metadata_clean!$B$2,--$C37<=--Campaign_Metadata_clean!$C$2),"SummerBeats", IF(AND(--$C37>=--Campaign_Metadata_clean!$B$3,--$C37<=--Campaign_Metadata_clean!$C$3),"Wrapped2024", IF(AND(--$C37>=--Campaign_Metadata_clean!$B$4,--$C37<=--Campaign_Metadata_clean!$C$4),"ChillVibes", IF(AND(--$C37>=--Campaign_Metadata_clean!$B$5,--$C37<=--Campaign_Metadata_clean!$C$5),"IndieWave","No Campaign")))) -> No Campaign | R37: =IF(AND(C37>=DATE(2025,1,10), C37<=DATE(2025,2,10)), "During", IF(C37<DATE(2025,1,10), "Before", "Other")) -> Before | S37: =IF(OR(X37="",Y37=""),"", IF(AND(C37>=X37-30,C37<X37),"Before", IF(AND(C37>=X37,C37<=Y37),"During","Other"))) | X37: =IFERROR( _xlfn.XLOOKUP(Q37, Campaign_Metadata_clean!A:A, Campaign_Metadata_clean!B:B), "") | Y37: =IFERROR( _xlfn.XLOOKUP(Q37, Campaign_Metadata_clean!A:A, Campaign_Metadata_clean!C:C), "") | Z37: =IFERROR( AVERAGEIFS(N:N, C:C, ">=" & X37-30, C:C, "<" & X37), 0) -> 0 | AA37: =IFERROR( AVERAGEIFS(N:N, C:C, ">=" & X37, C:C, "<=" & Y37), 0) -> 0 | AB37: =IF(AA37=0,0,(AB37-AA37)/AA37) -> 0
A38: SP037 | B38: Twitter | C38: 45804 | D38: Story | E38: Explore the latest podcasts now. | F38: 4095 | G38: 385 | H38: 400 | I38: 45300 | J38: 31795 | K38: 80 | L38: #MusicForEveryone | M38: #NowPlaying | N38: =(F38+G38+H38)/I38 -> 0.10772627 | O38: =RANK(N38,$N:$N,0) -> 89 | P38: =F38+G38+H38 -> 4880 | Q38: =IF(AND(--$C38>=--Campaign_Metadata_clean!$B$2,--$C38<=--Campaign_Metadata_clean!$C$2),"SummerBeats", IF(AND(--$C38>=--Campaign_Metadata_clean!$B$3,--$C38<=--Campaign_Metadata_clean!$C$3),"Wrapped2024", IF(AND(--$C38>=--Campaign_Metadata_clean!$B$4,--$C38<=--Campaign_Metadata_clean!$C$4),"ChillVibes", IF(AND(--$C38>=--Campaign_Metadata_clean!$B$5,--$C38<=--Campaign_Metadata_clean!$C$5),"IndieWave","No Campaign")))) -> No Campaign | R38: =IF(AND(C38>=DATE(2025,1,10), C38<=DATE(2025,2,10)), "During", IF(C38<DATE(2025,1,10), "Before", "Other")) -> Other | S38: =IF(OR(X38="",Y38=""),"", IF(AND(C38>=X38-30,C38<X38),"Before", IF(AND(C38>=X38,C38<=Y38),"During","Other"))) | X38: =IFERROR( _xlfn.XLOOKUP(Q38, Campaign_Metadata_clean!A:A, Campaign_Metadata_clean!B:B), "") | Y38: =IFERROR( _xlfn.XLOOKUP(Q38, Campaign_Metadata_clean!A:A, Campaign_Metadata_clean!C:C), "") | Z38: =IFERROR( AVERAGEIFS(N:N, C:C, ">=" & X38-30, C:C, "<" & X38), 0) -> 0 | AA38: =IFERROR( AVERAGEIFS(N:N, C:C, ">=" & X38, C:C, "<=" & Y38), 0) -> 0 | AB38: =IF(AA38=0,0,(AB38-AA38)/AA38) -> 0
